
<mujoco model="cheetah">
  <compiler angle="radian" coordinate="local" inertiafromgeom="true" settotalmass="14"/>
  <default>
    <joint armature=".1" damping=".01" limited="true" solimplimit="0 .8 .03" solreflimit=".02 1" stiffness="8"/>
    <geom type="box" mass=".0007" conaffinity="0" condim="3" contype="1" friction=".4 .1 .1" rgba="0.8 0.6 .4 0.5" solimp="0.0 0.8 0.01" solref="0.02 1"/>
    <motor ctrllimited="true" ctrlrange="-1 1"/>
    <site rgba=".9 .9 .9 1" size="0.001"/>
  </default>
  <size nstack="300000" nuser_geom="1"/>
  <option gravity="0 0 -9.81" timestep="0.01"/>
  <asset>
    <texture builtin="gradient" height="100" rgb1="1 1 1" rgb2="0 0 0" type="skybox" width="100"/>
    <texture builtin="flat" height="1278" mark="cross" markrgb="1 1 1" name="texgeom" random="0.01" rgb1="0.8 0.6 0.4" rgb2="0.8 0.6 0.4" type="cube" width="127"/>
    <texture builtin="checker" height="100" name="texplane" rgb1="0 0 0" rgb2="0.8 0.8 0.8" type="2d" width="100"/>
    <material name="MatPlane" reflectance="0.5" shininess="1" specular="1" texrepeat="60 60" texture="texplane"/>
    <material name="geom" texture="texgeom" texuniform="true"/>
  </asset>
  <worldbody>
    <light cutoff="100" diffuse="1 1 1" dir="-0 0 -1.3" directional="true" exponent="1" pos="0 0 1.3" specular=".1 .1 .1"/>
    <geom conaffinity="1" condim="3" material="MatPlane" name="floor" pos="0 0 0" rgba="0.8 0.9 0.8 1" size="40 40 40" type="plane"/>
    <site name="fwall" fromto="0.6 0 0 0.7 0 0" size="0.1" type="box" rgba=".9 .9 .9 0.5"/>
    <site name="bwall" fromto="-0.6 0 0 -0.7 0 0" size="0.1" type="box" rgba=".9 .9 .9 0.5"/>
    <site pos="0 0 0.1" size="0.01" type="sphere" rgba="0.8 0 0 0.30"/>


    <body name="torso" pos="0 0 .7">
      <camera name="track" mode="trackcom" pos="0 -1 0.1" xyaxes="1 0 0 0 0 1"/>
      <joint armature="0" axis="1 0 0" damping="0" limited="false" name="rootx" pos="0 0 0" stiffness="0" type="slide"/>
      <joint armature="0" axis="0 0 1" damping="0" limited="false" name="rootz" pos="0 0 0" stiffness="0" type="slide"/>
      <joint armature="0" axis="0 1 0" damping="0" limited="false" name="rooty" pos="0 0 0" stiffness="0" type="hinge"/>
      <geom name="mainbody" size=".03675 0.03075 0.012" mass=".134"/>
      <site name="sfub" pos=".025 0 .00884"/>
      <site name="sfdb" pos=".025 0 -.00884"/>
      <site name="sbub" pos="-.025 0 .00884"/>
      <site name="sbdb" pos="-.025 0 -.00884"/>
        
      <!-- front arm-->
      <body name="ffinger1" pos=".043 0 0">
        <joint axis="0 1 0" damping="6" name="ffinger1" pos="0 0 0" range="-.1 .1" stiffness="240" type="hinge"/>
        <geom name="ffinger1" size="0.00625 0.025 0.01"/>
        <body name="ffinger2" pos=".0125 0 0">
          <joint axis="0 1 0" damping="6" name="ffinger2" pos="0 0 0" range="-.1 .1" stiffness="240" type="hinge"/>
          <geom name="ffinger2" size="0.00625 0.025 0.01"/>
          <body name="ffinger3" pos=".0125 0 0">
            <joint axis="0 1 0" damping="6" name="ffinger3" pos="0 0 0" range="-.1 .1" stiffness="240" type="hinge"/>
            <geom name="ffinger3" size="0.00625 0.025 0.01"/>
            <site name="sfu1" pos="0 0 .01"/>
            <site name="sfd1" pos="0 0 -.01"/>
            <body name="ffinger4" pos=".0125 0 0">
              <joint axis="0 1 0" damping="6" name="ffinger4" pos="0 0 0" range="-.1 .1" stiffness="240" type="hinge"/>
              <geom name="ffinger4" size="0.00625 0.025 0.01"/>
              <body name="ffinger5" pos=".0125 0 0">
                <joint axis="0 1 0" damping="6" name="ffinger5" pos="0 0 0" range="-.1 .1" stiffness="240" type="hinge"/>
                <geom name="ffinger5" size="0.00625 0.025 0.01"/>
                <body name="ffinger6" pos=".0125 0 0">
                  <joint axis="0 1 0" damping="6" name="ffinger6" pos="0 0 0" range="-.1 .1" stiffness="240" type="hinge"/>
                  <geom name="ffinger6" size="0.00625 0.025 0.01"/>
                  <site name="sfu2" pos="0 0 .01"/>
                  <site name="sfd2" pos="0 0 -.01"/>
                  <body name="ffinger7" pos=".0125 0 0">
                    <joint axis="0 1 0" damping="6" name="ffinger7" pos="0 0 0" range="-.1 .1" stiffness="240" type="hinge"/>
                    <geom name="ffinger7" size="0.00625 0.025 0.01"/>
                    <body name="ffinger8" pos=".0125 0 0">
                      <joint axis="0 1 0" damping="6" name="ffinger8" pos="0 0 0" range="-.1 .1" stiffness="240" type="hinge"/>
                      <geom name="ffinger8" size="0.00625 0.025 0.01"/>
                      <body name="ffinger9" pos=".0125 0 0">
                        <joint axis="0 1 0" damping="6" name="ffinger9" pos="0 0 0" range="-.1 .1" stiffness="240" type="hinge"/>
                        <geom name="ffinger9" size="0.00625 0.025 0.01"/>
                        <site name="sfu3" pos="0 0 .01"/>
                        <site name="sfd3" pos="0 0 -.01"/>
                        <body name="ffinger10" pos=".0125 0 0">
                          <joint axis="0 1 0" damping="6" name="ffinger10" pos="0 0 0" range="-.1 .1" stiffness="240" type="hinge"/>
                          <geom name="ffinger10" size="0.00625 0.025 0.01"/>
                          <body name="ffinger11" pos=".0125 0 0">
                            <joint axis="0 1 0" damping="6" name="ffinger11" pos="0 0 0" range="-.1 .1" stiffness="240" type="hinge"/>
                            <geom name="ffinger11" size="0.00625 0.025 0.01"/>
                            <body name="ffinger12" pos=".0125 0 0">
                              <joint axis="0 1 0" damping="6" name="ffinger12" pos="0 0 0" range="-.1 .1" stiffness="240" type="hinge"/>
                              <geom name="ffinger12" size="0.00625 0.025 0.01"/>
                              <site name="sfu4" pos=".00625 0 .01"/>
                              <site name="sfd4" pos=".00625 0 -.01"/>
                            </body>
                          </body>
                        </body>
                      </body>
                    </body>
                  </body>
                </body>
              </body>
            </body>
          </body>
        </body>
      </body>
        
      <!--back arm-->
      <body name="bfinger1" pos="-.043 0 0">
        <joint axis="0 1 0" damping="6" name="bfinger1" pos="0 0 0" range="-.1 .1" stiffness="240" type="hinge"/>
        <geom name="bfinger1" size="0.00625 0.025 0.01"/>
        <body name="bfinger2" pos="-.0125 0 0">
          <joint axis="0 1 0" damping="6" name="bfinger2" pos="0 0 0" range="-.1 .1" stiffness="240" type="hinge"/>
          <geom name="bfinger2" size="0.00625 0.025 0.01"/>
          <body name="bfinger3" pos="-.0125 0 0">
            <joint axis="0 1 0" damping="6" name="bfinger3" pos="0 0 0" range="-.1 .1" stiffness="240" type="hinge"/>
            <geom name="bfinger3" size="0.00625 0.025 0.01"/>
            <site name="sbu1" pos="0 0 .01"/>
            <site name="sbd1" pos="0 0 -.01"/>
            <body name="bfinger4" pos="-.0125 0 0">
              <joint axis="0 1 0" damping="6" name="bfinger4" pos="0 0 0" range="-.1 .1" stiffness="240" type="hinge"/>
              <geom name="bfinger4" size="0.00625 0.025 0.01"/>
              <body name="bfinger5" pos="-.0125 0 0">
                <joint axis="0 1 0" damping="6" name="bfinger5" pos="0 0 0" range="-.1 .1" stiffness="240" type="hinge"/>
                <geom name="bfinger5" size="0.00625 0.025 0.01"/>
                <body name="bfinger6" pos="-.0125 0 0">
                  <joint axis="0 1 0" damping="6" name="bfinger6" pos="0 0 0" range="-.1 .1" stiffness="240" type="hinge"/>
                  <geom name="bfinger6" size="0.00625 0.025 0.01"/>
                  <site name="sbu2" pos="0 0 .01"/>
                  <site name="sbd2" pos="0 0 -.01"/>
                  <body name="bfinger7" pos="-.0125 0 0">
                    <joint axis="0 1 0" damping="6" name="bfinger7" pos="0 0 0" range="-.1 .1" stiffness="240" type="hinge"/>
                    <geom name="bfinger7" size="0.00625 0.025 0.01"/>
                    <body name="bfinger8" pos="-.0125 0 0">
                      <joint axis="0 1 0" damping="6" name="bfinger8" pos="0 0 0" range="-.1 .1" stiffness="240" type="hinge"/>
                      <geom name="bfinger8" size="0.00625 0.025 0.01"/>
                      <body name="bfinger9" pos="-.0125 0 0">
                        <joint axis="0 1 0" damping="6" name="bfinger9" pos="0 0 0" range="-.1 .1" stiffness="240" type="hinge"/>
                        <geom name="bfinger9" size="0.00625 0.025 0.01"/>
                        <site name="sbu3" pos="0 0 .01"/>
                        <site name="sbd3" pos="0 0 -.01"/>
                        <body name="bfinger10" pos="-.0125 0 0">
                          <joint axis="0 1 0" damping="6" name="bfinger10" pos="0 0 0" range="-.1 .1" stiffness="240" type="hinge"/>
                          <geom name="bfinger10" size="0.00625 0.025 0.01"/>
                          <body name="bfinger11" pos="-.0125 0 0">
                            <joint axis="0 1 0" damping="6" name="bfinger11" pos="0 0 0" range="-.1 .1" stiffness="240" type="hinge"/>
                            <geom name="bfinger11" size="0.00625 0.025 0.01"/>
                            <body name="bfinger12" pos="-.0125 0 0">
                              <joint axis="0 1 0" damping="6" name="bfinger12" pos="0 0 0" range="-.1 .1" stiffness="240" type="hinge"/>
                              <geom name="bfinger12" size="0.00625 0.025 0.01"/>
                              <site name="sbu4" pos="-.00625 0 .01"/>
                              <site name="sbd4" pos="-.00625 0 -.01"/>
                            </body>
                          </body>
                        </body>
                      </body>
                    </body>
                  </body>
                </body>
              </body>
            </body>
          </body>
        </body>
      </body>
    </body>
  </worldbody>
  <tendon>
    <spatial name="tfu" range="0.14898 0.17677" limited="true" width=".0005" rgba=".95 .3 .3 1">
      <site site="sfub"/>
      <site site="sfu1"/>
      <site site="sfu2"/>
      <site site="sfu3"/>
      <site site="sfu4"/>
    </spatial>
    <spatial name="tfd" range="0.14898 0.17677" limited="true" width=".0005" rgba=".95 .3 .3 1">
      <site site="sfdb"/>
      <site site="sfd1"/>
      <site site="sfd2"/>
      <site site="sfd3"/>
      <site site="sfd4"/>
    </spatial>
    <spatial name="tbu" range="0.14898 0.17677" limited="true" width=".0005" rgba=".95 .3 .3 1">
      <site site="sbub"/>
      <site site="sbu1"/>
      <site site="sbu2"/>
      <site site="sbu3"/>
      <site site="sbu4"/>
    </spatial>
    <spatial name="tbd" range="0.14898 0.17677" limited="true" width=".0005" rgba=".95 .3 .3 1">
      <site site="sbdb"/>
      <site site="sbd1"/>
      <site site="sbd2"/>
      <site site="sbd3"/>
      <site site="sbd4"/>
    </spatial>
  </tendon>
  <equality>
    <!--
    <joint joint1="ffinger1" joint2="ffinger2"/>
    <joint joint1="ffinger1" joint2="ffinger3"/>
    <joint joint1="ffinger1" joint2="ffinger4"/>
    <joint joint1="ffinger1" joint2="ffinger5"/>
    <joint joint1="ffinger1" joint2="ffinger6"/>
    <joint joint1="ffinger1" joint2="ffinger7"/>
    <joint joint1="ffinger1" joint2="ffinger8"/>
    <joint joint1="ffinger1" joint2="ffinger9"/>
    <joint joint1="ffinger1" joint2="ffinger10"/>
    <joint joint1="bfinger1" joint2="bfinger2"/>
    <joint joint1="bfinger1" joint2="bfinger3"/>
    <joint joint1="bfinger1" joint2="bfinger4"/>
    <joint joint1="bfinger1" joint2="bfinger5"/>
    <joint joint1="bfinger1" joint2="bfinger6"/>
    <joint joint1="bfinger1" joint2="bfinger7"/>
    <joint joint1="bfinger1" joint2="bfinger8"/>
    <joint joint1="bfinger1" joint2="bfinger9"/>
    <joint joint1="bfinger1" joint2="bfinger10"/>
    -->
  </equality>
  <actuator>
    <position kp="100" tendon="tfu" name="ffinger" ctrllimited="true" ctrlrange="-27.79 27.79" lengthrange="0.14898 0.17677"/>
    <position kp="100" tendon="tbu" name="bfinger" ctrllimited="true" ctrlrange="-27.79 27.79" lengthrange="0.14898 0.17677"/>
  </actuator>
  <sensor>
    <touch site="fwall" name="fwall"/>
    <touch site="bwall" name="bwall"/>
  </sensor>
</mujoco>