
<mujoco model="cheetah">
  <compiler angle="radian" coordinate="local" inertiafromgeom="true" settotalmass="14"/>
  <default>
    <joint armature=".1" damping=".01" limited="true" solimplimit="0 .8 .03" solreflimit=".02 1" stiffness="8"/>
    <geom conaffinity="0" condim="3" contype="1" friction=".4 .1 .1" rgba="0.8 0.6 .4 1" solimp="0.0 0.8 0.01" solref="0.02 1"/>
    <motor ctrllimited="true" ctrlrange="-1 1"/>
  </default>
  <size nstack="300000" nuser_geom="1"/>
  <option gravity="0 0 -9.81" timestep="0.01"/>
  <asset>
    <texture builtin="gradient" height="100" rgb1="1 1 1" rgb2="0 0 0" type="skybox" width="100"/>
    <texture builtin="flat" height="1278" mark="cross" markrgb="1 1 1" name="texgeom" random="0.01" rgb1="0.8 0.6 0.4" rgb2="0.8 0.6 0.4" type="cube" width="127"/>
    <texture builtin="checker" height="100" name="texplane" rgb1="0 0 0" rgb2="0.8 0.8 0.8" type="2d" width="100"/>
    <material name="MatPlane" reflectance="0.5" shininess="1" specular="1" texrepeat="60 60" texture="texplane"/>
    <material name="geom" texture="texgeom" texuniform="true"/>
  </asset>
  <worldbody>
    <light cutoff="100" diffuse="1 1 1" dir="-0 0 -1.3" directional="true" exponent="1" pos="0 0 1.3" specular=".1 .1 .1"/>
    <geom conaffinity="1" condim="3" material="MatPlane" name="floor" pos="0 0 0" rgba="0.8 0.9 0.8 1" size="40 40 40" type="plane"/>
    <site name="fwall" fromto="2.0 0 0 2.1 0 0" size="1.0" type="box"/>
    <site name="bwall" fromto="-2.0 0 0 -2.1 0 0" size="1.0" type="box"/>
    <site pos="0 0 0.1" size="0.1" type="sphere" rgba="0.8 0 0 0.30"/>


    <body name="torso" pos="0 0 .7">
      <camera name="track" mode="trackcom" pos="0 -3 0.3" xyaxes="1 0 0 0 0 1"/>
      <joint armature="0" axis="1 0 0" damping="0" limited="false" name="rootx" pos="0 0 0" stiffness="0" type="slide"/>
      <joint armature="0" axis="0 0 1" damping="0" limited="false" name="rootz" pos="0 0 0" stiffness="0" type="slide"/>
      <joint armature="0" axis="0 1 0" damping="0" limited="false" name="rooty" pos="0 0 0" stiffness="0" type="hinge"/>
      <geom fromto="-.06 0 0 .06 0 0" name="torso" size="0.03" type="box"/>
      <body name="ffinger1" pos=".06 0 0">
        <joint axis="0 1 0" damping="6" name="ffinger1" pos="0 0 0" range="-.1 .1" stiffness="240" type="hinge"/>
        <geom fromto="0 0 0 .02 0 0" name="ffinger1" size="0.03" type="box"/>
        <body name="ffinger2" pos=".02 0 0">
          <joint axis="0 1 0" damping="6" name="ffinger2" pos="0 0 0" range="-.1 .1" stiffness="240" type="hinge"/>
          <geom fromto="0 0 0 .02 0 0" name="ffinger2" size="0.03" type="box"/>
          <body name="ffinger3" pos=".02 0 0">
            <joint axis="0 1 0" damping="6" name="ffinger3" pos="0 0 0" range="-.1 .1" stiffness="240" type="hinge"/>
            <geom fromto="0 0 0 .02 0 0" name="ffinger3" size="0.03" type="box"/>
            <body name="ffinger4" pos=".02 0 0">
              <joint axis="0 1 0" damping="6" name="ffinger4" pos="0 0 0" range="-.1 .1" stiffness="240" type="hinge"/>
              <geom fromto="0 0 0 .02 0 0" name="ffinger4" size="0.03" type="box"/>
              <body name="ffinger5" pos=".02 0 0">
                <joint axis="0 1 0" damping="6" name="ffinger5" pos="0 0 0" range="-.1 .1" stiffness="240" type="hinge"/>
                <geom fromto="0 0 0 .02 0 0" name="ffinger5" size="0.03" type="box"/>
                <body name="ffinger6" pos=".02 0 0">
                  <joint axis="0 1 0" damping="6" name="ffinger6" pos="0 0 0" range="-.1 .1" stiffness="240" type="hinge"/>
                  <geom fromto="0 0 0 .02 0 0" name="ffinger6" size="0.03" type="box"/>
                  <body name="ffinger7" pos=".02 0 0">
                    <joint axis="0 1 0" damping="6" name="ffinger7" pos="0 0 0" range="-.1 .1" stiffness="240" type="hinge"/>
                    <geom fromto="0 0 0 .02 0 0" name="ffinger7" size="0.03" type="box"/>
                    <body name="ffinger8" pos=".02 0 0">
                      <joint axis="0 1 0" damping="6" name="ffinger8" pos="0 0 0" range="-.1 .1" stiffness="240" type="hinge"/>
                      <geom fromto="0 0 0 .02 0 0" name="ffinger8" size="0.03" type="box"/>
                      <body name="ffinger9" pos=".02 0 0">
                        <joint axis="0 1 0" damping="6" name="ffinger9" pos="0 0 0" range="-.1 .1" stiffness="240" type="hinge"/>
                        <geom fromto="0 0 0 .02 0 0" name="ffinger9" size="0.03" type="box"/>
                        <body name="ffinger10" pos=".02 0 0">
                          <joint axis="0 1 0" damping="6" name="ffinger10" pos="0 0 0" range="-.1 .1" stiffness="240" type="hinge"/>
                          <geom fromto="0 0 0 .02 0 0" name="ffinger10" size="0.03" type="box"/>
                        </body>
                      </body>
                    </body>
                  </body>
                </body>
              </body>
            </body>
          </body>
        </body>
      </body>
      <body name="bfinger1" pos="-.06 0 0">
        <joint axis="0 1 0" damping="6" name="bfinger1" pos="0 0 0" range="-.1 .1" stiffness="240" type="hinge"/>
        <geom fromto="-.02 0 0 0 0 0" name="bfinger1" size="0.03" type="box"/>
        <body name="bfinger2" pos="-.02 0 0">
          <joint axis="0 1 0" damping="6" name="bfinger2" pos="0 0 0" range="-.1 .1" stiffness="240" type="hinge"/>
          <geom fromto="-.02 0 0 0 0 0" name="bfinger2" size="0.03" type="box"/>
          <body name="bfinger3" pos="-.02 0 0">
            <joint axis="0 1 0" damping="6" name="bfinger3" pos="0 0 0" range="-.1 .1" stiffness="240" type="hinge"/>
            <geom fromto="-.02 0 0 0 0 0" name="bfinger3" size="0.03" type="box"/>
            <body name="bfinger4" pos="-.02 0 0">
              <joint axis="0 1 0" damping="6" name="bfinger4" pos="0 0 0" range="-.1 .1" stiffness="240" type="hinge"/>
              <geom fromto="-.02 0 0 0 0 0" name="bfinger4" size="0.03" type="box"/>
              <body name="bfinger5" pos="-.02 0 0">
                <joint axis="0 1 0" damping="6" name="bfinger5" pos="0 0 0" range="-.1 .1" stiffness="240" type="hinge"/>
                <geom fromto="-.02 0 0 0 0 0" name="bfinger5" size="0.03" type="box"/>
                <body name="bfinger6" pos="-.02 0 0">
                  <joint axis="0 1 0" damping="6" name="bfinger6" pos="0 0 0" range="-.1 .1" stiffness="240" type="hinge"/>
                  <geom fromto="-.02 0 0 0 0 0" name="bfinger6" size="0.03" type="box"/>
                  <body name="bfinger7" pos="-.02 0 0">
                    <joint axis="0 1 0" damping="6" name="bfinger7" pos="0 0 0" range="-.1 .1" stiffness="240" type="hinge"/>
                    <geom fromto="-.02 0 0 0 0 0" name="bfinger7" size="0.03" type="box"/>
                    <body name="bfinger8" pos="-.02 0 0">
                      <joint axis="0 1 0" damping="6" name="bfinger8" pos="0 0 0" range="-.1 .1" stiffness="240" type="hinge"/>
                      <geom fromto="-.02 0 0 0 0 0" name="bfinger8" size="0.03" type="box"/>
                      <body name="bfinger9" pos="-.02 0 0">
                        <joint axis="0 1 0" damping="6" name="bfinger9" pos="0 0 0" range="-.1 .1" stiffness="240" type="hinge"/>
                        <geom fromto="-.02 0 0 0 0 0" name="bfinger9" size="0.03" type="box"/>
                        <body name="bfinger10" pos="-.02 0 0">
                          <joint axis="0 1 0" damping="6" name="bfinger10" pos="0 0 0" range="-.1 .1" stiffness="240" type="hinge"/>
                          <geom fromto="-.02 0 0 0 0 0" name="bfinger10" size="0.03" type="box"/>
                        </body>
                      </body>
                    </body>
                  </body>
                </body>
              </body>
            </body>
          </body>
        </body>
      </body>
      <!-- <site name='tip'  pos='.15 0 .11'/>-->
      <!--<body name="bthigh" pos="-.5 0 0">
        <joint axis="0 1 0" damping="6" name="bthigh" pos="0 0 0" range="-.52 1.05" stiffness="240" type="hinge"/>
        <geom axisangle="0 1 0 -3.8" name="bthigh" pos=".1 0 -.13" size="0.03 .145" type="box"/>
        <body name="bshin" pos=".16 0 -.25">
          <joint axis="0 1 0" damping="4.5" name="bshin" pos="0 0 0" range="-.785 .785" stiffness="180" type="hinge"/>
          <geom axisangle="0 1 0 -2.03" name="bshin" pos="-.14 0 -.07" rgba="0.9 0.6 0.6 1" size="0.03 .15" type="box"/>
          <body name="bfoot" pos="-.28 0 -.14">
            <joint axis="0 1 0" damping="3" name="bfoot" pos="0 0 0" range="-.4 .785" stiffness="120" type="hinge"/>
            <geom axisangle="0 1 0 -.27" name="bfoot" pos=".03 0 -.097" rgba="0.9 0.6 0.6 1" size="0.03 .094" type="box"/>
          </body>
        </body>
      </body>-->
      <!--<body name="fthigh" pos=".5 0 0">
        <joint axis="0 1 0" damping="4.5" name="fthigh" pos="0 0 0" range="-1 .7" stiffness="180" type="hinge"/>
        <geom axisangle="0 1 0 .52" name="fthigh" pos="-.07 0 -.12" size="0.03 .133" type="box"/>
        <body name="fshin" pos="-.14 0 -.24">
          <joint axis="0 1 0" damping="3" name="fshin" pos="0 0 0" range="-1.2 .87" stiffness="120" type="hinge"/>
          <geom axisangle="0 1 0 -.6" name="fshin" pos=".065 0 -.09" rgba="0.9 0.6 0.6 1" size="0.03 .106" type="box"/>
          <body name="ffoot" pos=".13 0 -.18">
            <joint axis="0 1 0" damping="1.5" name="ffoot" pos="0 0 0" range="-.5 .5" stiffness="60" type="hinge"/>
            <geom axisangle="0 1 0 -.6" name="ffoot" pos=".045 0 -.07" rgba="0.9 0.6 0.6 1" size="0.03 .07" type="box"/>
          </body>
        </body>
      </body>-->
    </body>
  </worldbody>
  <equality>
    <joint joint1="ffinger1" joint2="ffinger2"/>
    <joint joint1="ffinger1" joint2="ffinger3"/>
    <joint joint1="ffinger1" joint2="ffinger4"/>
    <joint joint1="ffinger1" joint2="ffinger5"/>
    <joint joint1="ffinger1" joint2="ffinger6"/>
    <joint joint1="ffinger1" joint2="ffinger7"/>
    <joint joint1="ffinger1" joint2="ffinger8"/>
    <joint joint1="ffinger1" joint2="ffinger9"/>
    <joint joint1="ffinger1" joint2="ffinger10"/>
    <joint joint1="bfinger1" joint2="bfinger2"/>
    <joint joint1="bfinger1" joint2="bfinger3"/>
    <joint joint1="bfinger1" joint2="bfinger4"/>
    <joint joint1="bfinger1" joint2="bfinger5"/>
    <joint joint1="bfinger1" joint2="bfinger6"/>
    <joint joint1="bfinger1" joint2="bfinger7"/>
    <joint joint1="bfinger1" joint2="bfinger8"/>
    <joint joint1="bfinger1" joint2="bfinger9"/>
    <joint joint1="bfinger1" joint2="bfinger10"/>
  </equality>
  <actuator>
    <motor gear="300" joint="ffinger1" name="ffinger"/>
    <motor gear="300" joint="bfinger1" name="bfinger"/>
  </actuator>
  <sensor>
    <touch site="fwall" name="fwall"/>
    <touch site="bwall" name="bwall"/>
  </sensor>
</mujoco>