<mujoco model="cheetah">
  <compiler angle="radian" coordinate="local" inertiafromgeom="true" settotalmass="14"/>
  <default>
    <joint armature=".1" damping=".01" limited="true" solimplimit="0 .8 .03" solreflimit=".02 1" stiffness="8"/>
    <geom conaffinity="0" condim="3" contype="1" friction=".4 .1 .1" rgba="0.8 0.6 .4 1" solimp="0.0 0.8 0.01" solref="0.02 1"/>
    <motor ctrllimited="true" ctrlrange="-1 1"/>
  </default>
  <size nstack="300000" nuser_geom="1"/>
  <option gravity="0 0 -9.81" timestep="0.01"/>
  <asset>
    <texture builtin="gradient" height="100" rgb1="1 1 1" rgb2="0 0 0" type="skybox" width="100"/>
    <texture builtin="flat" height="1278" mark="cross" markrgb="1 1 1" name="texgeom" random="0.01" rgb1="0.8 0.6 0.4" rgb2="0.8 0.6 0.4" type="cube" width="127"/>
    <texture builtin="checker" height="100" name="texplane" rgb1="0 0 0" rgb2="0.8 0.8 0.8" type="2d" width="100"/>
    <material name="MatPlane" reflectance="0.5" shininess="1" specular="1" texrepeat="60 60" texture="texplane"/>
    <material name="geom" texture="texgeom" texuniform="true"/>
  </asset>
  <worldbody>
    <light cutoff="100" diffuse="1 1 1" dir="-0 0 -1.3" directional="true" exponent="1" pos="0 0 1.3" specular=".1 .1 .1"/>
    <geom conaffinity="1" condim="3" material="MatPlane" name="floor" pos="0 0 0" rgba="0.8 0.9 0.8 1" size="40 40 40" type="plane"/>
    <body name="torso" pos="0 0 .7">
      <camera name="track" mode="trackcom" pos="0 -3 0.3" xyaxes="1 0 0 0 0 1"/>
      <joint armature="0" axis="1 0 0" damping="0" limited="false" name="rootx" pos="0 0 0" stiffness="0" type="slide"/>
      <joint armature="0" axis="0 0 1" damping="0" limited="false" name="rootz" pos="0 0 0" stiffness="0" type="slide"/>
      <joint armature="0" axis="0 1 0" damping="0" limited="false" name="rooty" pos="0 0 0" stiffness="0" type="hinge"/>
      <geom fromto="-.3 0 0 .3 0 0" name="torso" size="0.046" type="capsule"/>
      <body name="ffinger1" pos=".3 0 0">
        <joint axis="0 1 0" damping="6" name="ffinger1" pos="0 0 0" range="-.1 .1" stiffness="240" type="hinge"/>
        <geom fromto="0 0 0 .05 0 0" name="ffinger1" size="0.046" type="capsule"/>
        <body name="ffinger2" pos=".05 0 0">
          <joint axis="0 1 0" damping="6" name="ffinger2" pos="0 0 0" range="-.1 .1" stiffness="240" type="hinge"/>
          <geom fromto="0 0 0 .05 0 0" name="ffinger2" size="0.046" type="capsule"/>
          <body name="ffinger3" pos=".05 0 0">
            <joint axis="0 1 0" damping="6" name="ffinger3" pos="0 0 0" range="-.1 .1" stiffness="240" type="hinge"/>
            <geom fromto="0 0 0 .05 0 0" name="ffinger3" size="0.046" type="capsule"/>
            <body name="ffinger4" pos=".05 0 0">
              <joint axis="0 1 0" damping="6" name="ffinger4" pos="0 0 0" range="-.1 .1" stiffness="240" type="hinge"/>
              <geom fromto="0 0 0 .05 0 0" name="ffinger4" size="0.046" type="capsule"/>
              <body name="ffinger5" pos=".05 0 0">
                <joint axis="0 1 0" damping="6" name="ffinger5" pos="0 0 0" range="-.1 .1" stiffness="240" type="hinge"/>
                <geom fromto="0 0 0 .05 0 0" name="ffinger5" size="0.046" type="capsule"/>
                <body name="ffinger6" pos=".05 0 0">
                  <joint axis="0 1 0" damping="6" name="ffinger6" pos="0 0 0" range="-.1 .1" stiffness="240" type="hinge"/>
                  <geom fromto="0 0 0 .05 0 0" name="ffinger6" size="0.046" type="capsule"/>
                  <body name="ffinger7" pos=".05 0 0">
                    <joint axis="0 1 0" damping="6" name="ffinger7" pos="0 0 0" range="-.1 .1" stiffness="240" type="hinge"/>
                    <geom fromto="0 0 0 .05 0 0" name="ffinger7" size="0.046" type="capsule"/>
                    <body name="ffinger8" pos=".05 0 0">
                      <joint axis="0 1 0" damping="6" name="ffinger8" pos="0 0 0" range="-.1 .1" stiffness="240" type="hinge"/>
                      <geom fromto="0 0 0 .05 0 0" name="ffinger8" size="0.046" type="capsule"/>
                      <body name="ffinger9" pos=".05 0 0">
                        <joint axis="0 1 0" damping="6" name="ffinger9" pos="0 0 0" range="-.1 .1" stiffness="240" type="hinge"/>
                        <geom fromto="0 0 0 .05 0 0" name="ffinger9" size="0.046" type="capsule"/>
                        <body name="ffinger10" pos=".05 0 0">
                          <joint axis="0 1 0" damping="6" name="ffinger10" pos="0 0 0" range="-.1 .1" stiffness="240" type="hinge"/>
                          <geom fromto="0 0 0 .05 0 0" name="ffinger10" size="0.046" type="capsule"/>
                        </body>
                      </body>
                    </body>
                  </body>
                </body>
              </body>
            </body>
          </body>
        </body>
      </body>
      <body name="bfinger1" pos="-.3 0 0">
        <joint axis="0 1 0" damping="6" name="bfinger1" pos="0 0 0" range="-.1 .1" stiffness="240" type="hinge"/>
        <geom fromto="-.05 0 0 0 0 0" name="bfinger1" size="0.046" type="capsule"/>
        <body name="bfinger2" pos="-.05 0 0">
          <joint axis="0 1 0" damping="6" name="bfinger2" pos="0 0 0" range="-.1 .1" stiffness="240" type="hinge"/>
          <geom fromto="-.05 0 0 0 0 0" name="bfinger2" size="0.046" type="capsule"/>
          <body name="bfinger3" pos="-.05 0 0">
            <joint axis="0 1 0" damping="6" name="bfinger3" pos="0 0 0" range="-.1 .1" stiffness="240" type="hinge"/>
            <geom fromto="-.05 0 0 0 0 0" name="bfinger3" size="0.046" type="capsule"/>
            <body name="bfinger4" pos="-.05 0 0">
              <joint axis="0 1 0" damping="6" name="bfinger4" pos="0 0 0" range="-.1 .1" stiffness="240" type="hinge"/>
              <geom fromto="-.05 0 0 0 0 0" name="bfinger4" size="0.046" type="capsule"/>
              <body name="bfinger5" pos="-.05 0 0">
                <joint axis="0 1 0" damping="6" name="bfinger5" pos="0 0 0" range="-.1 .1" stiffness="240" type="hinge"/>
                <geom fromto="-.05 0 0 0 0 0" name="bfinger5" size="0.046" type="capsule"/>
                <body name="bfinger6" pos="-.05 0 0">
                  <joint axis="0 1 0" damping="6" name="bfinger6" pos="0 0 0" range="-.1 .1" stiffness="240" type="hinge"/>
                  <geom fromto="-.05 0 0 0 0 0" name="bfinger6" size="0.046" type="capsule"/>
                  <body name="bfinger7" pos="-.05 0 0">
                    <joint axis="0 1 0" damping="6" name="bfinger7" pos="0 0 0" range="-.1 .1" stiffness="240" type="hinge"/>
                    <geom fromto="-.05 0 0 0 0 0" name="bfinger7" size="0.046" type="capsule"/>
                    <body name="bfinger8" pos="-.05 0 0">
                      <joint axis="0 1 0" damping="6" name="bfinger8" pos="0 0 0" range="-.1 .1" stiffness="240" type="hinge"/>
                      <geom fromto="-.05 0 0 0 0 0" name="bfinger8" size="0.046" type="capsule"/>
                      <body name="bfinger9" pos="-.05 0 0">
                        <joint axis="0 1 0" damping="6" name="bfinger9" pos="0 0 0" range="-.1 .1" stiffness="240" type="hinge"/>
                        <geom fromto="-.05 0 0 0 0 0" name="bfinger9" size="0.046" type="capsule"/>
                        <body name="bfinger10" pos="-.05 0 0">
                          <joint axis="0 1 0" damping="6" name="bfinger10" pos="0 0 0" range="-.1 .1" stiffness="240" type="hinge"/>
                          <geom fromto="-.05 0 0 0 0 0" name="bfinger10" size="0.046" type="capsule"/>
                        </body>
                      </body>
                    </body>
                  </body>
                </body>
              </body>
            </body>
          </body>
        </body>
      </body>
    </body>
  </worldbody>
  <equality>
    <joint joint1="ffinger1" joint2="ffinger2"/>
    <joint joint1="ffinger1" joint2="ffinger3"/>
    <joint joint1="ffinger1" joint2="ffinger4"/>
    <joint joint1="ffinger1" joint2="ffinger5"/>
    <joint joint1="ffinger1" joint2="ffinger6"/>
    <joint joint1="ffinger1" joint2="ffinger7"/>
    <joint joint1="ffinger1" joint2="ffinger8"/>
    <joint joint1="ffinger1" joint2="ffinger9"/>
    <joint joint1="ffinger1" joint2="ffinger10"/>
    <joint joint1="bfinger1" joint2="bfinger2"/>
    <joint joint1="bfinger1" joint2="bfinger3"/>
    <joint joint1="bfinger1" joint2="bfinger4"/>
    <joint joint1="bfinger1" joint2="bfinger5"/>
    <joint joint1="bfinger1" joint2="bfinger6"/>
    <joint joint1="bfinger1" joint2="bfinger7"/>
    <joint joint1="bfinger1" joint2="bfinger8"/>
    <joint joint1="bfinger1" joint2="bfinger9"/>
    <joint joint1="bfinger1" joint2="bfinger10"/>
  </equality>
  <actuator>
    <motor gear="300" joint="ffinger1" name="ffinger"/>
    <motor gear="300" joint="bfinger1" name="bfinger"/>
  </actuator>
</mujoco>